Workbook

Sheet Market Validation
B1: Market Validation
B2: Phase 0 · Prove demand before you commit capital
B4: DEMAND SIZING (CATCHMENT)
B5: Market layer | C5: Definition | D5: Annual room-nights | E5: Capturable % | F5: Room-nights | G5: Revenue @ ADR
B6: TAM — total area visitors | C6: All overnight visitors in catchment | D6: 480000 | E6: 1 | F6: =D6*E6 | G6: =F6*'Assumptions'!D6
B7: SAM — 4★ boutique segment | C7: Mid-upscale leisure + business | D7: 96000 | E7: 0.2 | F7: =D7*E7 | G7: =F7*'Assumptions'!D6
B8: SOM — realistic year-1 share | C8: What this hotel can win | D8: 6300 | E8: 0.013125 | F8: =D8*E8 | G8: =F8*'Assumptions'!D6
B10: Your capacity (rooms×365×occ) room-nights | D10: ='Assumptions'!D5*365*'Assumptions'!D7
B11: SOM room-nights should be ≤ your capacity. If SOM > capacity you are capacity-constrained (good problem); if far below, demand is thin.
B13: INDUSTRY BENCHMARK BAND (CITED)
B14: Metric | C14: Low | D14: Typical | E14: High | F14: Source
B15: ADR — 4★ average daily rate | C15: 127 | D15: 144 | E15: 241 | F15: Fáilte Ireland Hotel Survey Nov/Dec 2024 (4★ ADR €143.50–€144.49; county range €127–€241)
B16: Occupancy — 4★ | C16: 0.602 | D16: 0.7 | E16: 0.741 | F16: Fáilte Ireland Hotel Survey 2024 (4★ occ 60.2% Dec → 74.1% Nov)
B17: RevPAR — 4★ | C17: 86.42 | D17: 97 | E17: 107.07 | F17: Fáilte Ireland Hotel Survey 2024 (4★ RevPAR €86.42 Dec → €107.07 Nov)
B18: Labour cost (% of total revenue) | C18: 0.25 | D18: 0.31 | E18: 0.35 | F18: Hospitality labour benchmark 25–35% of revenue; US long-run 31.2% (Mandelbaum/CBRE; altametrics)
B19: F&B cost (% of F&B revenue) | C19: 0.18 | D19: 0.28 | E19: 0.35 | F19: USALI F&B cost-of-sales; academic luxury 17.86% (US) – 23.87% (Asia)
B20: Rooms dept cost ex-payroll (% of rooms rev) | C20: 0.08 | D20: 0.12 | E20: 0.18 | F20: USALI rooms departmental expense (rooms expense ~27–28% incl. labour; ex-labour ~8–18%)
B21: GOP margin (% of total revenue) | C21: 0.3 | D21: 0.36 | E21: 0.383 | F21: HotelData Q4-2025 full-year GOP margin 38.3%; academic luxury 33.2–36.7%
B22: Compare your Assumptions against these published bands; stay within Typical–High to be credible to lenders/grant assessors.
B24: COMPETITOR MATRIX
B25: Competitor | C25: Rooms | D25: Est. ADR € | E25: Rating /5 | F25: Key strength | G25: Your edge vs them
B26: The Harbour Townhouse | C26: 28 | D26: 145 | E26: 4.3 | F26: Sea views, spa
B27: City Mews Boutique | C27: 19 | D27: 128 | E27: 4.5 | F27: Design-led, central
B28: The Old Mill Hotel | C28: 32 | D28: 119 | E28: 4 | F28: Free parking, events
B29: Riverside Guesthouse | C29: 12 | D29: 99 | E29: 4.4 | F29: Owner-hosted, breakfast
B31: Competitor avg ADR | D31: =AVERAGE(D26:D29)
B32: Your planned ADR | D32: ='Assumptions'!D6
B33: Your ADR vs market | D33: =IFERROR('Assumptions'!D6/AVERAGE(D26:D29)-1,"")
B35: LOCATION SCORING (WEIGHTED)
B36: Factor | C36: Weight | D36: Score /10 | E36: Weighted
B37: Footfall / visibility | C37: 0.2 | D37: 8 | E37: =C37*D37
B38: Transport access | C38: 0.15 | D38: 7 | E38: =C38*D38
B39: Nearby demand drivers | C39: 0.2 | D39: 9 | E39: =C39*D39
B40: Competition density | C40: 0.15 | D40: 6 | E40: =C40*D40
B41: Lease cost vs ADR | C41: 0.15 | D41: 7 | E41: =C41*D41
B42: Planning / fit-out ease | C42: 0.15 | D42: 8 | E42: =C42*D42
B43: Location score / 10 | E43: =SUM(E37:E42) | F43: =IF(E43="","",IF(E43>=7,"🟢 On target",IF(E43>=5,"🟡 Watch","🔴 Action")))
B45: PHASE 0 GO / NO-GO GATE
B46: SOM room-nights within capacity | F46: =IF(F8<= ('Assumptions'!D5*365),"PASS","REVIEW")
B47: ADR competitive (within ±15% of market) | F47: =IF(ABS(D33)<=0.15,"PASS","REVIEW")
...

Sheet Assumptions
B1: Assumptions & Inputs
B2: Single source of truth — edit the orange cells; everything links here
B4: DEMAND & RATE
B5: Rooms available | D5: 24
B6: ADR — average daily rate | D6: 135 | F6: 4★ boutique IE €110–180
B7: Occupancy | D7: 0.72 | F7: annualised; 65–80% typical
B8: RevPAR (ADR × occupancy) | D8: ='Assumptions'!D6*'Assumptions'!D7
B9: F&B + other revenue (% of rooms) | D9: 0.28
B10: Rooms revenue / yr | D10: ='Assumptions'!D5*365*'Assumptions'!D8
B11: Total revenue / yr | D11: ='Assumptions'!D10*(1+'Assumptions'!D9)
B13: COST RATIOS
B14: Payroll (% of total revenue) | D14: 0.3
B15: F&B cost (% of F&B revenue) | D15: 0.3
B16: Rooms cost (% of rooms revenue) | D16: 0.1
B17: Utilities (% of total revenue) | D17: 0.05
B18: Sales & marketing (% of revenue) | D18: 0.06
B19: Admin & general (% of revenue) | D19: 0.05
B20: Property: rent/rates/insurance (%) | D20: 0.12
B22: CAPITAL EXPENDITURE (FIT-OUT LED — LEASED PROPERTY)
B23: Lease deposit & legal | D23: 45000
B24: Building refurbishment & fit-out | D24: 240000
B25: FF&E (rooms, beds, furniture) | D25: 120000
B26: Kitchen & F&B equipment | D26: 55000
B27: IT, PMS, POS & networking | D27: 30000
B28: Branding, signage & website | D28: 25000
B29: Pre-opening payroll & training | D29: 35000
B30: Working capital buffer | D30: 50000
B31: Total capex required | D31: =SUM(D23:D30)
B33: FUNDING MIX
B34: Founder equity (incl. SURE refund) | D34: 180000 | F34: =IF($D$34="","",D34/SUM($D$34:$D$37))
B35: LEO Priming grant | D35: 80000 | F35: =IF($D$35="","",D35/SUM($D$34:$D$37))
B36: Bank / SBCI term loan | D36: 300000 | F36: =IF($D$36="","",D36/SUM($D$34:$D$37))
B37: Microfinance Ireland loan | D37: 40000 | F37: =IF($D$37="","",D37/SUM($D$34:$D$37))
B38: Total funding raised | D38: =SUM(D34:D37)
B39: Funding vs capex (surplus/gap) | D39: ='Assumptions'!D38-'Assumptions'!D31
B41: SOURCES & BENCHMARK NOTES
B42: ADR/occupancy/RevPAR: Fáilte Ireland Hotel Survey 2024 — 4★ ADR €143.50–€144.49, occupancy 60.2% (Dec) → 74.1% (Nov), RevPAR €86.42–€107.07.
B43: Cost ratios: hospitality labour 25–35% of revenue (US long-run 31.2%); USALI F&B cost-of-sales; GOP margin ~36–38% (HotelData 2025). See `startup_benchmarks` table.
B44: Grant/funding figures: Local Enterprise Office (localenterprise.ie), Microfinance Ireland, SBCI, Fáilte Ireland investment schemes.
B45: Figures are seed assumptions — replace the orange cells with your own quotes and verified local data before relying on them.
...
