Workbook

Sheet Business Plan
B1: Business Plan
B2: Phase 1 · Service definition + 3-scenario annual P&L
B4: EXECUTIVE SUMMARY
B5: A 24-room 4★ boutique hotel; ADR €135, target occupancy 72%, RevPAR €97.
B6: Positioning: design-led, service-rich, direct-booking-first to beat OTA commission and lift repeat stays.
B7: Funded by a blended stack (founder equity incl. SURE refund, LEO grant, term loan, MFI) — see Phase 2.
B9: SERVICE DEFINITION
B10: Revenue stream | C10: What it is | D10: Pricing basis
B11: Rooms | C11: 24 keys, 3 room grades | D11: ADR + dynamic
B12: Food & beverage | C12: Breakfast, bar, small-plates | D12: Per cover / menu
B13: Events & meetings | C13: Small functions, private dining | D13: Day-delegate / hire
B14: Ancillary | C14: Parking, late checkout, retail | D14: Add-on
B16: 3-SCENARIO ANNUAL P&L (LINKED TO ASSUMPTIONS)
B17: Low / Base / High flex occupancy & ADR via the multipliers row. Every figure links to the Assumptions sheet.
B18: Line (€/yr) | C18: Low | D18: Base | E18: High | F18: Driver
B19: Occupancy × / ADR × | C19: 0.85 | D19: 1 | E19: 1.12 | F19: occupancy flex
B20: ADR multiplier | C20: 0.93 | D20: 1 | E20: 1.08 | F20: rate flex
B21: Revenue
B22: Rooms revenue | C22: ='Assumptions'!D5*365*('Assumptions'!D6*C20)*('Assumptions'!D7*C19) | D22: ='Assumptions'!D5*365*('Assumptions'!D6*D20)*('Assumptions'!D7*D19) | E22: ='Assumptions'!D5*365*('Assumptions'!D6*E20)*('Assumptions'!D7*E19) | F22: rooms×365×ADR×occ
B23: F&B + other revenue | C23: =C22*'Assumptions'!D9 | D23: =D22*'Assumptions'!D9 | E23: =E22*'Assumptions'!D9 | F23: % of rooms
B24: Total revenue | C24: =C22+C23 | D24: =D22+D23 | E24: =E22+E23
B25: Costs
B26: Payroll | C26: =C24*'Assumptions'!D14 | D26: =D24*'Assumptions'!D14 | E26: =E24*'Assumptions'!D14 | F26: % of revenue
B27: F&B cost of sales | C27: =C23*'Assumptions'!D15 | D27: =D23*'Assumptions'!D15 | E27: =E23*'Assumptions'!D15 | F27: % of F&B rev
B28: Rooms cost (hskpg etc.) | C28: =C22*'Assumptions'!D16 | D28: =D22*'Assumptions'!D16 | E28: =E22*'Assumptions'!D16 | F28: % of rooms rev
B29: Utilities | C29: =C24*'Assumptions'!D17 | D29: =D24*'Assumptions'!D17 | E29: =E24*'Assumptions'!D17 | F29: % of revenue
B30: Sales & marketing | C30: =C24*'Assumptions'!D18 | D30: =D24*'Assumptions'!D18 | E30: =E24*'Assumptions'!D18 | F30: % of revenue
B31: Admin & general | C31: =C24*'Assumptions'!D19 | D31: =D24*'Assumptions'!D19 | E31: =E24*'Assumptions'!D19 | F31: % of revenue
B32: Property (rent/rates/ins.) | C32: =C24*'Assumptions'!D20 | D32: =D24*'Assumptions'!D20 | E32: =E24*'Assumptions'!D20 | F32: % of revenue
B33: Total costs | C33: =SUM(C26:C32) | D33: =SUM(D26:D32) | E33: =SUM(E26:E32)
B34: Gross operating profit | C34: =C24-C33 | D34: =D24-D33 | E34: =E24-E33
B35: GOP margin | C35: =IFERROR(C34/C24,0) | D35: =IFERROR(D34/D24,0) | E35: =IFERROR(E34/E24,0) | F35: GOP ÷ revenue
B37: PHASE 1 GO / NO-GO GATE (BASE CASE)
B38: Base GOP ≥ €250k? | D38: =D34 | E38: =IF(D34>=250000,"PASS","REVIEW")
B53: ASSET-FORGE · LEANTA Turnkey Pack · Boutique Hotel · v1.0 · 04/06/2026 · Phase 1 of 6

Sheet Assumptions
B1: Assumptions & Inputs
B2: Single source of truth — edit the orange cells; everything links here
B4: DEMAND & RATE
B5: Rooms available | D5: 24
B6: ADR — average daily rate | D6: 135 | F6: 4★ boutique IE €110–180
B7: Occupancy | D7: 0.72 | F7: annualised; 65–80% typical
B8: RevPAR (ADR × occupancy) | D8: ='Assumptions'!D6*'Assumptions'!D7
B9: F&B + other revenue (% of rooms) | D9: 0.28
B10: Rooms revenue / yr | D10: ='Assumptions'!D5*365*'Assumptions'!D8
B11: Total revenue / yr | D11: ='Assumptions'!D10*(1+'Assumptions'!D9)
B13: COST RATIOS
B14: Payroll (% of total revenue) | D14: 0.3
B15: F&B cost (% of F&B revenue) | D15: 0.3
B16: Rooms cost (% of rooms revenue) | D16: 0.1
B17: Utilities (% of total revenue) | D17: 0.05
B18: Sales & marketing (% of revenue) | D18: 0.06
B19: Admin & general (% of revenue) | D19: 0.05
B20: Property: rent/rates/insurance (%) | D20: 0.12
B22: CAPITAL EXPENDITURE (FIT-OUT LED — LEASED PROPERTY)
B23: Lease deposit & legal | D23: 45000
B24: Building refurbishment & fit-out | D24: 240000
B25: FF&E (rooms, beds, furniture) | D25: 120000
B26: Kitchen & F&B equipment | D26: 55000
B27: IT, PMS, POS & networking | D27: 30000
B28: Branding, signage & website | D28: 25000
B29: Pre-opening payroll & training | D29: 35000
B30: Working capital buffer | D30: 50000
B31: Total capex required | D31: =SUM(D23:D30)
B33: FUNDING MIX
B34: Founder equity (incl. SURE refund) | D34: 180000 | F34: =IF($D$34="","",D34/SUM($D$34:$D$37))
B35: LEO Priming grant | D35: 80000 | F35: =IF($D$35="","",D35/SUM($D$34:$D$37))
B36: Bank / SBCI term loan | D36: 300000 | F36: =IF($D$36="","",D36/SUM($D$34:$D$37))
B37: Microfinance Ireland loan | D37: 40000 | F37: =IF($D$37="","",D37/SUM($D$34:$D$37))
B38: Total funding raised | D38: =SUM(D34:D37)
B39: Funding vs capex (surplus/gap) | D39: ='Assumptions'!D38-'Assumptions'!D31
B41: SOURCES & BENCHMARK NOTES
B42: ADR/occupancy/RevPAR benchmarks: Fáilte Ireland & STR Ireland hotel performance reports (4-star/boutique ranges).
B43: Grant/funding figures: Local Enterprise Office (localenterprise.ie), Microfinance Ireland, SBCI, Fáilte Ireland investment schemes.
B44: Cost ratios (payroll ~30%, F&B cost ~30%): USALI hotel P&L conventions.
B45: Figures are seed assumptions — replace the orange cells with your own quotes and verified local data before relying on them.
...
