Workbook

Sheet Capital & Funding
B1: Capital Raising
B2: Phase 2 · Capex, funding mix, debt service & 12-month cash-flow
B4: USES VS SOURCES
B5: Total capex (uses) | D5: ='Assumptions'!D31
B6: Total funding (sources) | D6: ='Assumptions'!D38
B7: Surplus / (gap) | D7: ='Assumptions'!D38-'Assumptions'!D31
B9: DEBT SERVICE (TERM LOAN)
B10: Loan principal € | D10: 300000
B11: Interest rate (APR) | D11: 0.075
B12: Term (years) | D12: 7
B13: Monthly repayment € | D13: =IFERROR(-PMT(D11/12,D12*12,D10),0)
B14: Annual debt service € | D14: =D13*12
B16: 12-MONTH OPENING CASH-FLOW (WITH OCCUPANCY RAMP)
B17: Revenue ramps from a soft-open fraction up to steady state. Costs scale with revenue; debt service is constant. Closing cash carries forward.
B18: Line (€) | C18: M1 | D18: M2 | E18: M3 | F18: M4 | G18: M5 | H18: M6 | I18: M7 | J18: M8 | K18: M9 | L18: M10 | M18: M11 | N18: M12 | O18: Year
B19: Occupancy ramp × | C19: 0.45 | D19: 0.55 | E19: 0.62 | F19: 0.68 | G19: 0.74 | H19: 0.8 | I19: 0.85 | J19: 0.88 | K19: 0.85 | L19: 0.8 | M19: 0.74 | N19: 0.7
B20: Revenue | C20: =('Assumptions'!D11/12)*(C19/'Assumptions'!D7) | D20: =('Assumptions'!D11/12)*(D19/'Assumptions'!D7) | E20: =('Assumptions'!D11/12)*(E19/'Assumptions'!D7) | F20: =('Assumptions'!D11/12)*(F19/'Assumptions'!D7) | G20: =('Assumptions'!D11/12)*(G19/'Assumptions'!D7) | H20: =('Assumptions'!D11/12)*(H19/'Assumptions'!D7) | I20: =('Assumptions'!D11/12)*(I19/'Assumptions'!D7) | J20: =('Assumptions'!D11/12)*(J19/'Assumptions'!D7) | K20: =('Assumptions'!D11/12)*(K19/'Assumptions'!D7) | L20: =('Assumptions'!D11/12)*(L19/'Assumptions'!D7) | M20: =('Assumptions'!D11/12)*(M19/'Assumptions'!D7) | N20: =('Assumptions'!D11/12)*(N19/'Assumptions'!D7) | O20: =SUM(C20:N20)
B21: Payroll | C21: =C20*'Assumptions'!D14 | D21: =D20*'Assumptions'!D14 | E21: =E20*'Assumptions'!D14 | F21: =F20*'Assumptions'!D14 | G21: =G20*'Assumptions'!D14 | H21: =H20*'Assumptions'!D14 | I21: =I20*'Assumptions'!D14 | J21: =J20*'Assumptions'!D14 | K21: =K20*'Assumptions'!D14 | L21: =L20*'Assumptions'!D14 | M21: =M20*'Assumptions'!D14 | N21: =N20*'Assumptions'!D14 | O21: =SUM(C21:N21)
B22: Other operating costs | C22: =C20*('Assumptions'!D15*'Assumptions'!D9+'Assumptions'!D16+'Assumptions'!D17+'Assumptions'!D18+'Assumptions'!D19+'Assumptions'!D20) | D22: =D20*('Assumptions'!D15*'Assumptions'!D9+'Assumptions'!D16+'Assumptions'!D17+'Assumptions'!D18+'Assumptions'!D19+'Assumptions'!D20) | E22: =E20*('Assumptions'!D15*'Assumptions'!D9+'Assumptions'!D16+'Assumptions'!D17+'Assumptions'!D18+'Assumptions'!D19+'Assumptions'!D20) | F22: =F20*('Assumptions'!D15*'Assumptions'!D9+'Assumptions'!D16+'Assumptions'!D17+'Assumptions'!D18+'Assumptions'!D19+'Assumptions'!D20) | G22: =G20*('Assumptions'!D15*'Assumptions'!D9+'Assumptions'!D16+'Assumptions'!D17+'Assumptions'!D18+'Assumptions'!D19+'Assumptions'!D20) | H22: =H20*('Assumptions'!D15*'Assumptions'!D9+'Assumptions'!D16+'Assumptions'!D17+'Assumptions'!D18+'Assumptions'!D19+'Assumptions'!D20) | I22: =I20*('Assumptions'!D15*'Assumptions'!D9+'Assumptions'!D16+'Assumptions'!D17+'Assumptions'!D18+'Assumptions'!D19+'Assumptions'!D20) | J22: =J20*('Assumptions'!D15*'Assumptions'!D9+'Assumptions'!D16+'Assumptions'!D17+'Assumptions'!D18+'Assumptions'!D19+'Assumptions'!D20) | K22: =K20*('Assumptions'!D15*'Assumptions'!D9+'Assumptions'!D16+'Assumptions'!D17+'Assumptions'!D18+'Assumptions'!D19+'Assumptions'!D20) | L22: =L20*('Assumptions'!D15*'Assumptions'!D9+'Assumptions'!D16+'Assumptions'!D17+'Assumptions'!D18+'Assumptions'!D19+'Assumptions'!D20) | M22: =M20*('Assumptions'!D15*'Assumptions'!D9+'Assumptions'!D16+'Assumptions'!D17+'Assumptions'!D18+'Assumptions'!D19+'Assumptions'!D20) | N22: =N20*('Assumptions'!D15*'Assumptions'!D9+'Assumptions'!D16+'Assumptions'!D17+'Assumptions'!D18+'Assumptions'!D19+'Assumptions'!D20) | O22: =SUM(C22:N22)
B23: Debt service | C23: =D13 | D23: =D13 | E23: =D13 | F23: =D13 | G23: =D13 | H23: =D13 | I23: =D13 | J23: =D13 | K23: =D13 | L23: =D13 | M23: =D13 | N23: =D13 | O23: =SUM(C23:N23)
B24: Net cash flow | C24: =C20-C21-C22-C23 | D24: =D20-D21-D22-D23 | E24: =E20-E21-E22-E23 | F24: =F20-F21-F22-F23 | G24: =G20-G21-G22-G23 | H24: =H20-H21-H22-H23 | I24: =I20-I21-I22-I23 | J24: =J20-J21-J22-J23 | ... N24: =N20-N21-N22-N23 | O24: =SUM(C24:N24)
B25: Opening cash | C25: ='Assumptions'!D38-'Assumptions'!D31 | D25: =C26 | E25: =D26 | F25: =E26 | G25: =F26 | H25: =G26 | I25: =H26 | J25: =I26 | K25: =J26 | ... N25: =M26
B26: Closing cash | C26: =C25+C24 | D26: =D25+D24 | E26: =E25+E24 | F26: =F25+F24 | G26: =G25+G24 | H26: =H25+H24 | I26: =I25+I24 | J26: =J25+J24 | ... N26: =N25+N24 | O26: =N26
B28: RUNWAY & COVER
B29: Lowest monthly closing cash € | D29: =MIN(C26:N26)
B30: Min cash buffer status | D30: =IF(MIN(C26:N26)>=0,"🟢 Positive all year","🔴 Goes negative — raise more")
B31: DSCR (GOP ÷ debt service) | D31: =IFERROR((O20-O21-O22)/(O23),0)
B33: ASSET-FORGE · LEANTA Turnkey Pack · Boutique Hotel · v1.0 · 04/06/2026 · Phase 2 of 6

Sheet Assumptions
B1: Assumptions & Inputs
B2: Single source of truth — edit the orange cells; everything links here
B4: DEMAND & RATE
B5: Rooms available | D5: 24
B6: ADR — average daily rate | D6: 135 | F6: 4★ boutique IE €110–180
B7: Occupancy | D7: 0.72 | F7: annualised; 65–80% typical
B8: RevPAR (ADR × occupancy) | D8: ='Assumptions'!D6*'Assumptions'!D7
B9: F&B + other revenue (% of rooms) | D9: 0.28
B10: Rooms revenue / yr | D10: ='Assumptions'!D5*365*'Assumptions'!D8
B11: Total revenue / yr | D11: ='Assumptions'!D10*(1+'Assumptions'!D9)
B13: COST RATIOS
B14: Payroll (% of total revenue) | D14: 0.3
B15: F&B cost (% of F&B revenue) | D15: 0.3
B16: Rooms cost (% of rooms revenue) | D16: 0.1
B17: Utilities (% of total revenue) | D17: 0.05
B18: Sales & marketing (% of revenue) | D18: 0.06
B19: Admin & general (% of revenue) | D19: 0.05
B20: Property: rent/rates/insurance (%) | D20: 0.12
B22: CAPITAL EXPENDITURE (FIT-OUT LED — LEASED PROPERTY)
B23: Lease deposit & legal | D23: 45000
B24: Building refurbishment & fit-out | D24: 240000
B25: FF&E (rooms, beds, furniture) | D25: 120000
B26: Kitchen & F&B equipment | D26: 55000
B27: IT, PMS, POS & networking | D27: 30000
B28: Branding, signage & website | D28: 25000
B29: Pre-opening payroll & training | D29: 35000
B30: Working capital buffer | D30: 50000
B31: Total capex required | D31: =SUM(D23:D30)
B33: FUNDING MIX
B34: Founder equity (incl. SURE refund) | D34: 180000 | F34: =IF($D$34="","",D34/SUM($D$34:$D$37))
B35: LEO Priming grant | D35: 80000 | F35: =IF($D$35="","",D35/SUM($D$34:$D$37))
B36: Bank / SBCI term loan | D36: 300000 | F36: =IF($D$36="","",D36/SUM($D$34:$D$37))
B37: Microfinance Ireland loan | D37: 40000 | F37: =IF($D$37="","",D37/SUM($D$34:$D$37))
B38: Total funding raised | D38: =SUM(D34:D37)
B39: Funding vs capex (surplus/gap) | D39: ='Assumptions'!D38-'Assumptions'!D31
B41: SOURCES & BENCHMARK NOTES
B42: ADR/occupancy/RevPAR benchmarks: Fáilte Ireland & STR Ireland hotel performance reports (4-star/boutique ranges).
B43: Grant/funding figures: Local Enterprise Office (localenterprise.ie), Microfinance Ireland, SBCI, Fáilte Ireland investment schemes.
B44: Cost ratios (payroll ~30%, F&B cost ~30%): USALI hotel P&L conventions.
B45: Figures are seed assumptions — replace the orange cells with your own quotes and verified local data before relying on them.
...
