Workbook

Sheet Procurement
B1: Procurement
B2: Phase 3 · Vendors, fit-out budget, RFQ compare & purchase orders
B4: VENDOR MASTER
B5: Vendor | C5: Category | D5: Lead time (wk) | E5: Payment terms | F5: Rating /5 | G5: Contact | H5: Approved?
B6: Murphy FF&E Ltd | C6: Furniture & fit-out | D6: 8 | E6: 30% / 70% | F6: 4.5 | H6: Yes
B7: Atlantic Linen Co | C7: Linen & textiles | D7: 3 | E7: Net 30 | F7: 4.2 | H7: Yes
B8: KitchenPro | C8: Kitchen equipment | D8: 6 | E8: 50% deposit | F8: 4 | H8: Yes
B9: BrightIT Systems | C9: PMS/POS/network | D9: 4 | E9: Net 14 | F9: 4.6 | H9: Pending
B10: GreenClean Supplies | C10: Housekeeping consumables | D10: 1 | E10: Net 30 | F10: 4.1 | H10: Pending
B12: RFQ COMPARISON — AUTO-FLAGS LOWEST QUOTE
B13: Item | C13: Quote A € | D13: Quote B € | E13: Quote C € | F13: Lowest € | G13: Best vendor | H13: Saving vs A
B14: 36 bedroom furniture sets | C14: 64000 | D14: 59500 | E14: 61200 | F14: =MIN(C14:E14) | G14: =CHOOSE(MATCH(MIN(C14:E14),C14:E14,0),"Quote A","Quote B","Quote C") | H14: =C14-F14
B15: Commercial kitchen line | C15: 52000 | D15: 55000 | E15: 49900 | F15: =MIN(C15:E15) | G15: =CHOOSE(MATCH(MIN(C15:E15),C15:E15,0),"Quote A","Quote B","Quote C") | H15: =C15-F15
B16: PMS + POS (3-yr) | C16: 18000 | D16: 21000 | E16: 17400 | F16: =MIN(C16:E16) | G16: =CHOOSE(MATCH(MIN(C16:E16),C16:E16,0),"Quote A","Quote B","Quote C") | H16: =C16-F16
B17: Bed linen (par 3) | C17: 14500 | D17: 13900 | E17: 15200 | F17: =MIN(C17:E17) | G17: =CHOOSE(MATCH(MIN(C17:E17),C17:E17,0),"Quote A","Quote B","Quote C") | H17: =C17-F17
B18: Total lowest-quote spend | F18: =SUM(F14:F17) | H18: =SUM(H14:H17)
B20: PURCHASE ORDER REGISTER
B21: PO # | C21: Vendor | D21: Description | E21: Order date | F21: Due date | G21: Amount € | H21: Status
B22: PO-001 | C22: Murphy FF&E Ltd | D22: Bedroom furniture x24 | G22: 59500 | H22: Confirmed
B23: PO-002 | C23: KitchenPro | D23: Kitchen line install | G23: 49900 | H23: Sent
B24: PO-003 | C24: BrightIT Systems | D24: PMS + POS rollout | G24: 17400 | H24: Draft
B36: Committed spend (PO register) | G36: =SUM(G22:G35)
B37: Capex budget (Assumptions) | G37: ='Assumptions'!D31
B38: Budget remaining | G38: ='Assumptions'!D31-SUM(G22:G35)
B40: ASSET-FORGE · LEANTA Turnkey Pack · Boutique Hotel · v1.0 · 04/06/2026 · Phase 3 of 6

Sheet Assumptions
B1: Assumptions & Inputs
B2: Single source of truth — edit the orange cells; everything links here
B4: DEMAND & RATE
B5: Rooms available | D5: 24
B6: ADR — average daily rate | D6: 135 | F6: 4★ boutique IE €110–180
B7: Occupancy | D7: 0.72 | F7: annualised; 65–80% typical
B8: RevPAR (ADR × occupancy) | D8: ='Assumptions'!D6*'Assumptions'!D7
B9: F&B + other revenue (% of rooms) | D9: 0.28
B10: Rooms revenue / yr | D10: ='Assumptions'!D5*365*'Assumptions'!D8
B11: Total revenue / yr | D11: ='Assumptions'!D10*(1+'Assumptions'!D9)
B13: COST RATIOS
B14: Payroll (% of total revenue) | D14: 0.3
B15: F&B cost (% of F&B revenue) | D15: 0.3
B16: Rooms cost (% of rooms revenue) | D16: 0.1
B17: Utilities (% of total revenue) | D17: 0.05
B18: Sales & marketing (% of revenue) | D18: 0.06
B19: Admin & general (% of revenue) | D19: 0.05
B20: Property: rent/rates/insurance (%) | D20: 0.12
B22: CAPITAL EXPENDITURE (FIT-OUT LED — LEASED PROPERTY)
B23: Lease deposit & legal | D23: 45000
B24: Building refurbishment & fit-out | D24: 240000
B25: FF&E (rooms, beds, furniture) | D25: 120000
B26: Kitchen & F&B equipment | D26: 55000
B27: IT, PMS, POS & networking | D27: 30000
B28: Branding, signage & website | D28: 25000
B29: Pre-opening payroll & training | D29: 35000
B30: Working capital buffer | D30: 50000
B31: Total capex required | D31: =SUM(D23:D30)
B33: FUNDING MIX
B34: Founder equity (incl. SURE refund) | D34: 180000 | F34: =IF($D$34="","",D34/SUM($D$34:$D$37))
B35: LEO Priming grant | D35: 80000 | F35: =IF($D$35="","",D35/SUM($D$34:$D$37))
B36: Bank / SBCI term loan | D36: 300000 | F36: =IF($D$36="","",D36/SUM($D$34:$D$37))
B37: Microfinance Ireland loan | D37: 40000 | F37: =IF($D$37="","",D37/SUM($D$34:$D$37))
B38: Total funding raised | D38: =SUM(D34:D37)
B39: Funding vs capex (surplus/gap) | D39: ='Assumptions'!D38-'Assumptions'!D31
B41: SOURCES & BENCHMARK NOTES
B42: ADR/occupancy/RevPAR benchmarks: Fáilte Ireland & STR Ireland hotel performance reports (4-star/boutique ranges).
B43: Grant/funding figures: Local Enterprise Office (localenterprise.ie), Microfinance Ireland, SBCI, Fáilte Ireland investment schemes.
B44: Cost ratios (payroll ~30%, F&B cost ~30%): USALI hotel P&L conventions.
B45: Figures are seed assumptions — replace the orange cells with your own quotes and verified local data before relying on them.
...
