Workbook

Sheet Team & Payroll
B1: Team Building
B2: Phase 4 · Org design, hiring tracker & payroll budget (PRSI/pension)
B4: STAFFING PLAN & PAYROLL BUDGET
B5: Employer PRSI ~11.05% and pension ~5% are added on gross. Total payroll should land near the Assumptions payroll % of revenue.
B6: Role | C6: Dept | D6: FTE | E6: Gross €/yr | F6: PRSI+pension | G6: Total cost € | H6: Notes
B7: On-cost loading (PRSI+pension) | F7: 0.16
B8: General Manager | C8: Leadership | D8: 1 | E8: 55000 | F8: =D8*E8*F7 | G8: =D8*E8*(1+F7)
B9: Front Office Manager | C9: Front office | D9: 1 | E9: 38000 | F9: =D9*E9*F7 | G9: =D9*E9*(1+F7)
B10: Receptionist | C10: Front office | D10: 2.5 | E10: 30000 | F10: =D10*E10*F7 | G10: =D10*E10*(1+F7)
B11: Head Housekeeper | C11: Housekeeping | D11: 1 | E11: 34000 | F11: =D11*E11*F7 | G11: =D11*E11*(1+F7)
B12: Room Attendant | C12: Housekeeping | D12: 3 | E12: 27500 | F12: =D12*E12*F7 | G12: =D12*E12*(1+F7)
B13: Head Chef | C13: F&B | D13: 1 | E13: 48000 | F13: =D13*E13*F7 | G13: =D13*E13*(1+F7)
B14: Chef de Partie / KP | C14: F&B | D14: 2 | E14: 31000 | F14: =D14*E14*F7 | G14: =D14*E14*(1+F7)
B15: F&B / Bar Attendant | C15: F&B | D15: 2.5 | E15: 28000 | F15: =D15*E15*F7 | G15: =D15*E15*(1+F7)
B16: Maintenance | C16: Facilities | D16: 1 | E16: 36000 | F16: =D16*E16*F7 | G16: =D16*E16*(1+F7)
B17: Total FTE / payroll | D17: =SUM(D8:D16) | G17: =SUM(G8:G16)
B18: Payroll as % of revenue | G18: =IFERROR(G17/'Assumptions'!D11,0)
B20: RECRUITMENT TRACKER
B21: Role | C21: Stage | D21: Candidate | E21: Interview score /10 | F21: Offer status | G21: Start date | H21: Notes
B22: General Manager
B23: Front Office Manager
B24: Receptionist
B25: Head Housekeeper
B26: Room Attendant
B27: Head Chef
B28: Chef de Partie / KP
B29: F&B / Bar Attendant
B30: Maintenance
B33: ASSET-FORGE · LEANTA Turnkey Pack · Boutique Hotel · v1.0 · 04/06/2026 · Phase 4 of 6

Sheet Assumptions
B1: Assumptions & Inputs
B2: Single source of truth — edit the orange cells; everything links here
B4: DEMAND & RATE
B5: Rooms available | D5: 24
B6: ADR — average daily rate | D6: 135 | F6: 4★ boutique IE €110–180
B7: Occupancy | D7: 0.72 | F7: annualised; 65–80% typical
B8: RevPAR (ADR × occupancy) | D8: ='Assumptions'!D6*'Assumptions'!D7
B9: F&B + other revenue (% of rooms) | D9: 0.28
B10: Rooms revenue / yr | D10: ='Assumptions'!D5*365*'Assumptions'!D8
B11: Total revenue / yr | D11: ='Assumptions'!D10*(1+'Assumptions'!D9)
B13: COST RATIOS
B14: Payroll (% of total revenue) | D14: 0.3
B15: F&B cost (% of F&B revenue) | D15: 0.3
B16: Rooms cost (% of rooms revenue) | D16: 0.1
B17: Utilities (% of total revenue) | D17: 0.05
B18: Sales & marketing (% of revenue) | D18: 0.06
B19: Admin & general (% of revenue) | D19: 0.05
B20: Property: rent/rates/insurance (%) | D20: 0.12
B22: CAPITAL EXPENDITURE (FIT-OUT LED — LEASED PROPERTY)
B23: Lease deposit & legal | D23: 45000
B24: Building refurbishment & fit-out | D24: 240000
B25: FF&E (rooms, beds, furniture) | D25: 120000
B26: Kitchen & F&B equipment | D26: 55000
B27: IT, PMS, POS & networking | D27: 30000
B28: Branding, signage & website | D28: 25000
B29: Pre-opening payroll & training | D29: 35000
B30: Working capital buffer | D30: 50000
B31: Total capex required | D31: =SUM(D23:D30)
B33: FUNDING MIX
B34: Founder equity (incl. SURE refund) | D34: 180000 | F34: =IF($D$34="","",D34/SUM($D$34:$D$37))
B35: LEO Priming grant | D35: 80000 | F35: =IF($D$35="","",D35/SUM($D$34:$D$37))
B36: Bank / SBCI term loan | D36: 300000 | F36: =IF($D$36="","",D36/SUM($D$34:$D$37))
B37: Microfinance Ireland loan | D37: 40000 | F37: =IF($D$37="","",D37/SUM($D$34:$D$37))
B38: Total funding raised | D38: =SUM(D34:D37)
B39: Funding vs capex (surplus/gap) | D39: ='Assumptions'!D38-'Assumptions'!D31
B41: SOURCES & BENCHMARK NOTES
B42: ADR/occupancy/RevPAR benchmarks: Fáilte Ireland & STR Ireland hotel performance reports (4-star/boutique ranges).
B43: Grant/funding figures: Local Enterprise Office (localenterprise.ie), Microfinance Ireland, SBCI, Fáilte Ireland investment schemes.
B44: Cost ratios (payroll ~30%, F&B cost ~30%): USALI hotel P&L conventions.
B45: Figures are seed assumptions — replace the orange cells with your own quotes and verified local data before relying on them.
...
