Workbook

Sheet Daily Data Entry
B1: Daily Data Entry
B2: Phase 5 · Log the day — the dashboard reads from here
B4: Date | C4: Rooms sold | D4: Rooms avail | E4: Rooms rev € | F4: F&B rev € | G4: F&B cost € | H4: Direct bookings | I4: Total bookings | J4: Repeat guests | K4: NPS responses
B5: 46174 | C5: 18 | D5: 24 | E5: 2484 | F5: 690 | G5: 221 | H5: 7 | I5: 17 | J5: 5 | K5: 60
B6: 46175 | C6: 20 | D6: 24 | E6: 2760 | F6: 760 | G6: 243 | H6: 8 | I6: 18 | J6: 6 | K6: 58
B7: 46176 | C7: 17 | D7: 24 | E7: 2295 | F7: 640 | G7: 205 | H7: 6 | I7: 16 | J7: 4 | K7: 62
B8: 46177 | C8: 21 | D8: 24 | E8: 2898 | F8: 800 | G8: 256 | H8: 9 | I8: 19 | J8: 7 | K8: 55
B9: 46178 | C9: 22 | D9: 24 | E9: 3036 | F9: 840 | G9: 269 | H9: 8 | I9: 20 | J9: 6 | K9: 59
B10: 46179 | C10: 19 | D10: 24 | E10: 2622 | F10: 720 | G10: 230 | H10: 7 | I10: 18 | J10: 5 | K10: 61
B11: 46180 | C11: 16 | D11: 24 | E11: 2160 | F11: 600 | G11: 192 | H11: 6 | I11: 15 | J11: 4 | K11: 57
B37: ASSET-FORGE · LEANTA Turnkey Pack · Boutique Hotel · v1.0 · 04/06/2026 · Phase 5 · data entry

Sheet KPI Dashboard
B1: Operations KPI Dashboard
B2: Phase 5 · 15 live hotel metrics vs target with 🟢🟡🔴 status
B4: METRICS VS TARGET
B5: KPI | C5: Actual | D5: Target | E5: Status | F5: How it's measured
B6: Occupancy | C6: =IFERROR(SUM('Daily Data Entry'!C5:C35)/SUM('Daily Data Entry'!D5:D35),0) | D6: 0.72 | E6: =IF(C6="","",IF(C6>=0.7,"🟢 On target",IF(C6>=0.55,"🟡 Watch","🔴 Action"))) | F6: Rooms sold ÷ rooms available
B7: ADR (Avg Daily Rate) | C7: =IFERROR(SUM('Daily Data Entry'!E5:E35)/SUM('Daily Data Entry'!C5:C35),0) | D7: 135 | E7: =IF(C7="","",IF(C7>=130,"🟢 On target",IF(C7>=110,"🟡 Watch","🔴 Action"))) | F7: Rooms revenue ÷ rooms sold
B8: RevPAR | C8: =IFERROR(SUM('Daily Data Entry'!E5:E35)/SUM('Daily Data Entry'!D5:D35),0) | D8: 97 | E8: =IF(C8="","",IF(C8>=90,"🟢 On target",IF(C8>=70,"🟡 Watch","🔴 Action"))) | F8: ADR × occupancy
B9: GOPPAR | C9: =IFERROR(((SUM('Daily Data Entry'!E5:E35)+SUM('Daily Data Entry'!F5:F35))*(1-'Assumptions'!D14-'Assumptions'!D17-'Assumptions'!D18-'Assumptions'!D19-'Assumptions'!D20)-SUM('Daily Data Entry'!G5:G35))/SUM('Daily Data Entry'!D5:D35),0) | D9: 45 | E9: =IF(C9="","",IF(C9>=40,"🟢 On target",IF(C9>=25,"🟡 Watch","🔴 Action"))) | F9: Gross operating profit per available room
B10: Guest NPS | C10: =IFERROR(AVERAGE('Daily Data Entry'!L5:L35),0) | D10: 60 | E10: =IF(C10="","",IF(C10>=50,"🟢 On target",IF(C10>=30,"🟡 Watch","🔴 Action"))) | F10: Net promoter score from guest surveys
B11: Labour cost % | C11: 0.31 | D11: 0.3 | E11: =IF(C11="","",IF(C11<=0.32,"🟢 On target",IF(C11<=0.4,"🟡 Watch","🔴 Action"))) | F11: Total payroll ÷ total revenue
B12: F&B cost % | C12: =IFERROR(SUM('Daily Data Entry'!G5:G35)/SUM('Daily Data Entry'!F5:F35),0) | D12: 0.3 | E12: =IF(C12="","",IF(C12<=0.3,"🟢 On target",IF(C12<=0.38,"🟡 Watch","🔴 Action"))) | F12: Cost of F&B sales ÷ F&B revenue
B13: Repeat guest % | C13: =IFERROR(SUM('Daily Data Entry'!K5:K35)/SUM('Daily Data Entry'!J5:J35),0) | D13: 0.25 | E13: =IF(C13="","",IF(C13>=0.25,"🟢 On target",IF(C13>=0.15,"🟡 Watch","🔴 Action"))) | F13: Returning guests ÷ total guests
B14: ALOS (nights) | C14: 1.9 | D14: 2 | E14: =IF(C14="","",IF(C14>=1.8,"🟢 On target",IF(C14>=1.3,"🟡 Watch","🔴 Action"))) | F14: Average length of stay
B15: Direct booking % | C15: =IFERROR(SUM('Daily Data Entry'!I5:I35)/SUM('Daily Data Entry'!J5:J35),0) | D15: 0.4 | E15: =IF(C15="","",IF(C15>=0.4,"🟢 On target",IF(C15>=0.25,"🟡 Watch","🔴 Action"))) | F15: Direct bookings ÷ total (vs OTA)
B16: Room turnaround (min) | C16: 33 | D16: 30 | E16: =IF(C16="","",IF(C16<=30,"🟢 On target",IF(C16<=45,"🟡 Watch","🔴 Action"))) | F16: Avg housekeeping turnaround per room
B17: Maint. response (hrs) | C17: 5 | D17: 4 | E17: =IF(C17="","",IF(C17<=4,"🟢 On target",IF(C17<=12,"🟡 Watch","🔴 Action"))) | F17: Avg time to resolve a maintenance ticket
B18: Staff turnover % | C18: 0.28 | D18: 0.25 | E18: =IF(C18="","",IF(C18<=0.25,"🟢 On target",IF(C18<=0.45,"🟡 Watch","🔴 Action"))) | F18: Annualised staff leavers ÷ headcount
B19: Complaints / 100 stays | C19: 4 | D19: 3 | E19: =IF(C19="","",IF(C19<=3,"🟢 On target",IF(C19<=7,"🟡 Watch","🔴 Action"))) | F19: Logged complaints per 100 stays
B20: Payment collection % | C20: 0.97 | D20: 0.98 | E20: =IF(C20="","",IF(C20>=0.98,"🟢 On target",IF(C20>=0.92,"🟡 Watch","🔴 Action"))) | F20: Cash collected ÷ invoiced
B22: HEADLINE SCORECARD
B24: OCCUPANCY | E24: ADR (AVG DAILY RATE) | H24: REVPAR | K24: GOPPAR
B25: =IFERROR(C6,0) | E25: =IFERROR(C7,0) | H25: =IFERROR(C8,0) | K25: =IFERROR(C9,0)
B28: STATUS SUMMARY
B29: 🟢 On target | D29: =COUNTIF(E6:E20,"*On target*")
B30: 🟡 Watch | D30: =COUNTIF(E6:E20,"*Watch*")
B31: 🔴 Action | D31: =COUNTIF(E6:E20,"*Action*")
B46: ASSET-FORGE · LEANTA Turnkey Pack · Boutique Hotel · v1.0 · 04/06/2026 · Phase 5 of 6

Sheet Assumptions
B1: Assumptions & Inputs
B2: Single source of truth — edit the orange cells; everything links here
B4: DEMAND & RATE
B5: Rooms available | D5: 24
B6: ADR — average daily rate | D6: 135 | F6: 4★ boutique IE €110–180
B7: Occupancy | D7: 0.72 | F7: annualised; 65–80% typical
B8: RevPAR (ADR × occupancy) | D8: ='Assumptions'!D6*'Assumptions'!D7
B9: F&B + other revenue (% of rooms) | D9: 0.28
B10: Rooms revenue / yr | D10: ='Assumptions'!D5*365*'Assumptions'!D8
B11: Total revenue / yr | D11: ='Assumptions'!D10*(1+'Assumptions'!D9)
B13: COST RATIOS
B14: Payroll (% of total revenue) | D14: 0.3
B15: F&B cost (% of F&B revenue) | D15: 0.3
B16: Rooms cost (% of rooms revenue) | D16: 0.1
B17: Utilities (% of total revenue) | D17: 0.05
B18: Sales & marketing (% of revenue) | D18: 0.06
B19: Admin & general (% of revenue) | D19: 0.05
B20: Property: rent/rates/insurance (%) | D20: 0.12
B22: CAPITAL EXPENDITURE (FIT-OUT LED — LEASED PROPERTY)
B23: Lease deposit & legal | D23: 45000
B24: Building refurbishment & fit-out | D24: 240000
B25: FF&E (rooms, beds, furniture) | D25: 120000
B26: Kitchen & F&B equipment | D26: 55000
B27: IT, PMS, POS & networking | D27: 30000
B28: Branding, signage & website | D28: 25000
B29: Pre-opening payroll & training | D29: 35000
B30: Working capital buffer | D30: 50000
B31: Total capex required | D31: =SUM(D23:D30)
B33: FUNDING MIX
B34: Founder equity (incl. SURE refund) | D34: 180000 | F34: =IF($D$34="","",D34/SUM($D$34:$D$37))
B35: LEO Priming grant | D35: 80000 | F35: =IF($D$35="","",D35/SUM($D$34:$D$37))
B36: Bank / SBCI term loan | D36: 300000 | F36: =IF($D$36="","",D36/SUM($D$34:$D$37))
B37: Microfinance Ireland loan | D37: 40000 | F37: =IF($D$37="","",D37/SUM($D$34:$D$37))
B38: Total funding raised | D38: =SUM(D34:D37)
B39: Funding vs capex (surplus/gap) | D39: ='Assumptions'!D38-'Assumptions'!D31
B41: SOURCES & BENCHMARK NOTES
B42: ADR/occupancy/RevPAR: Fáilte Ireland Hotel Survey 2024 — 4★ ADR €143.50–€144.49, occupancy 60.2% (Dec) → 74.1% (Nov), RevPAR €86.42–€107.07.
B43: Cost ratios: hospitality labour 25–35% of revenue (US long-run 31.2%); USALI F&B cost-of-sales; GOP margin ~36–38% (HotelData 2025). See `startup_benchmarks` table.
B44: Grant/funding figures: Local Enterprise Office (localenterprise.ie), Microfinance Ireland, SBCI, Fáilte Ireland investment schemes.
B45: Figures are seed assumptions — replace the orange cells with your own quotes and verified local data before relying on them.
...
