Workbook

Sheet Capital Grant Outline
B1: Fáilte Ireland — Tourism Capital Grant
B2: Two-stage scheme for larger tourism capital projects (€200k+)
B4: Capital grants for projects that grow overseas visitors, create jobs and support the destination brands. Two-stage process; State Aid rules apply. Source: failteireland.ie.
B5: ELIGIBILITY & STATE-AID SCREEN
B6: Project capital value ≥ €200,000 | G6: =IF('Assumptions'!D31>=200000,"PASS","Below threshold")
B7: Tax-cleared tourism business | G7: =IF(TRUE,"Confirm","Confirm")
B8: Grows overseas visitor / off-season demand | G8: =IF(TRUE,"Confirm","Confirm")
B9: Within State-Aid limits (de minimis / GBER) | G9: =IF(TRUE,"Confirm","Confirm")
B11: Project rationale
B12: How the project boosts overseas visitor growth, jobs and the destination brand.
B14: CAPITAL COST SCHEDULE (AUTO-LINKED)
B15: Capital item | C15: Cost € | D15: Grant ask €
B16: Lease deposit & legal | D16: =INDEX('Assumptions'!D23:D30,MATCH(B16,'Assumptions'!B23:B30,0))
B17: Building refurbishment & fit-out | D17: =INDEX('Assumptions'!D23:D30,MATCH(B17,'Assumptions'!B23:B30,0))
B18: FF&E (rooms, beds, furniture) | D18: =INDEX('Assumptions'!D23:D30,MATCH(B18,'Assumptions'!B23:B30,0))
B19: Kitchen & F&B equipment | D19: =INDEX('Assumptions'!D23:D30,MATCH(B19,'Assumptions'!B23:B30,0))
B20: IT, PMS, POS & networking | D20: =INDEX('Assumptions'!D23:D30,MATCH(B20,'Assumptions'!B23:B30,0))
B21: Branding, signage & website | D21: =INDEX('Assumptions'!D23:D30,MATCH(B21,'Assumptions'!B23:B30,0))
B22: Pre-opening payroll & training | D22: =INDEX('Assumptions'!D23:D30,MATCH(B22,'Assumptions'!B23:B30,0))
B23: Working capital buffer | D23: =INDEX('Assumptions'!D23:D30,MATCH(B23,'Assumptions'!B23:B30,0))
B24: Total project / grant ask | D24: =SUM(D16:D23) | F24: =SUM(F16:F23)
B25: Match-funding (own + other) | D25: ='Assumptions'!D38-SUM(F16:F23)

Sheet Assumptions
B1: Assumptions & Inputs
B2: Single source of truth — edit the orange cells; everything links here
B4: DEMAND & RATE
B5: Rooms available | D5: 24
B6: ADR — average daily rate | D6: 135 | F6: 4★ boutique IE €110–180
B7: Occupancy | D7: 0.72 | F7: annualised; 65–80% typical
B8: RevPAR (ADR × occupancy) | D8: ='Assumptions'!D6*'Assumptions'!D7
B9: F&B + other revenue (% of rooms) | D9: 0.28
B10: Rooms revenue / yr | D10: ='Assumptions'!D5*365*'Assumptions'!D8
B11: Total revenue / yr | D11: ='Assumptions'!D10*(1+'Assumptions'!D9)
B13: COST RATIOS
B14: Payroll (% of total revenue) | D14: 0.3
B15: F&B cost (% of F&B revenue) | D15: 0.3
B16: Rooms cost (% of rooms revenue) | D16: 0.1
B17: Utilities (% of total revenue) | D17: 0.05
B18: Sales & marketing (% of revenue) | D18: 0.06
B19: Admin & general (% of revenue) | D19: 0.05
B20: Property: rent/rates/insurance (%) | D20: 0.12
B22: CAPITAL EXPENDITURE (FIT-OUT LED — LEASED PROPERTY)
B23: Lease deposit & legal | D23: 45000
B24: Building refurbishment & fit-out | D24: 240000
B25: FF&E (rooms, beds, furniture) | D25: 120000
B26: Kitchen & F&B equipment | D26: 55000
B27: IT, PMS, POS & networking | D27: 30000
B28: Branding, signage & website | D28: 25000
B29: Pre-opening payroll & training | D29: 35000
B30: Working capital buffer | D30: 50000
B31: Total capex required | D31: =SUM(D23:D30)
B33: FUNDING MIX
B34: Founder equity (incl. SURE refund) | D34: 180000 | F34: =IF($D$34="","",D34/SUM($D$34:$D$37))
B35: LEO Priming grant | D35: 80000 | F35: =IF($D$35="","",D35/SUM($D$34:$D$37))
B36: Bank / SBCI term loan | D36: 300000 | F36: =IF($D$36="","",D36/SUM($D$34:$D$37))
B37: Microfinance Ireland loan | D37: 40000 | F37: =IF($D$37="","",D37/SUM($D$34:$D$37))
B38: Total funding raised | D38: =SUM(D34:D37)
B39: Funding vs capex (surplus/gap) | D39: ='Assumptions'!D38-'Assumptions'!D31
B41: SOURCES & BENCHMARK NOTES
B42: ADR/occupancy/RevPAR benchmarks: Fáilte Ireland & STR Ireland hotel performance reports (4-star/boutique ranges).
B43: Grant/funding figures: Local Enterprise Office (localenterprise.ie), Microfinance Ireland, SBCI, Fáilte Ireland investment schemes.
B44: Cost ratios (payroll ~30%, F&B cost ~30%): USALI hotel P&L conventions.
B45: Figures are seed assumptions — replace the orange cells with your own quotes and verified local data before relying on them.
...
