Workbook

Sheet Application
B1: LEO Priming / Business Expansion Grant
B2: Local Enterprise Office · application — mirrors the official e-form
B4: Up to 50% of qualifying non-salary costs; max €80,000 (€150,000 exceptional). Priming = first 18 months; Business Expansion = growth phase after 18 months. Source: localenterprise.ie.
B5: 1 · APPLICANT & LEGAL DETAILS
B6: Business / trading name
B7: Legal form (sole trader/partnership/Ltd)
B8: Company / tax reg. number
B9: Directors & % shareholding
B10: Business address
B11: Premises owned / leased (+ lease term)
B13: 2 · Promoter background & qualifications
B14: Relevant experience, education and track record of each promoter (min ~150 words).
... B29: 5 · YEAR-1 EXPENDITURE (AUTO-LINKED FROM ASSUMPTIONS CAPEX)
B30: Cost item | C30: Total cost € | D30: Eligible? (non-salary) | E30: Grant-eligible €
B31: Lease deposit & legal | D31: =INDEX('Assumptions'!D23:D30,MATCH(B31,'Assumptions'!B23:B30,0)) | E31: Yes | F31: =IF(E31="Yes",D31,0)
B32: Building refurbishment & fit-out | D32: =INDEX('Assumptions'!D23:D30,MATCH(B32,'Assumptions'!B23:B30,0)) | E32: Yes | F32: =IF(E32="Yes",D32,0)
B33: FF&E (rooms, beds, furniture) | D33: =INDEX('Assumptions'!D23:D30,MATCH(B33,'Assumptions'!B23:B30,0)) | E33: Yes | F33: =IF(E33="Yes",D33,0)
B34: Kitchen & F&B equipment | D34: =INDEX('Assumptions'!D23:D30,MATCH(B34,'Assumptions'!B23:B30,0)) | E34: Yes | F34: =IF(E34="Yes",D34,0)
B35: IT, PMS, POS & networking | D35: =INDEX('Assumptions'!D23:D30,MATCH(B35,'Assumptions'!B23:B30,0)) | E35: Yes | F35: =IF(E35="Yes",D35,0)
B36: Branding, signage & website | D36: =INDEX('Assumptions'!D23:D30,MATCH(B36,'Assumptions'!B23:B30,0)) | E36: Review | F36: =IF(E36="Yes",D36,0)
B37: Pre-opening payroll & training | D37: =INDEX('Assumptions'!D23:D30,MATCH(B37,'Assumptions'!B23:B30,0)) | E37: Review | F37: =IF(E37="Yes",D37,0)
B38: Working capital buffer | D38: =INDEX('Assumptions'!D23:D30,MATCH(B38,'Assumptions'!B23:B30,0)) | E38: Review | F38: =IF(E38="Yes",D38,0)
B39: Total eligible expenditure | F39: =SUM(F31:F38)
B41: GRANT CALCULATION
B42: Match rate | D42: 0.5
B43: Jobs created (FTE) | D43: 6
B44: Grant cap (€80k std / €150k exceptional) | D44: 80000
B45: Indicative grant (lower of match × eligible, cap) | D45: =MIN(F39*D42,D44)
B46: Employment support guide (max €15k/FTE) | D46: =D43*15000
B48: REQUIRED ATTACHMENTS
B49: Completed & signed application form | I49: ☐ To do
B50: CV of main applicant / promoter | I50: ☐ To do
B51: Quotations for key costs (3 quotes for any item over €5,000) | I51: ☐ To do
B52: Most recent certified accounts (existing businesses) | I52: ☐ To do
B53: Business plan (see Phase 1 workbook) | I53: ☐ To do
B54: Tax clearance confirmation | I54: ☐ To do

Sheet Assumptions
B1: Assumptions & Inputs
B2: Single source of truth — edit the orange cells; everything links here
B4: DEMAND & RATE
B5: Rooms available | D5: 24
B6: ADR — average daily rate | D6: 135 | F6: 4★ boutique IE €110–180
B7: Occupancy | D7: 0.72 | F7: annualised; 65–80% typical
B8: RevPAR (ADR × occupancy) | D8: ='Assumptions'!D6*'Assumptions'!D7
B9: F&B + other revenue (% of rooms) | D9: 0.28
B10: Rooms revenue / yr | D10: ='Assumptions'!D5*365*'Assumptions'!D8
B11: Total revenue / yr | D11: ='Assumptions'!D10*(1+'Assumptions'!D9)
B13: COST RATIOS
B14: Payroll (% of total revenue) | D14: 0.3
B15: F&B cost (% of F&B revenue) | D15: 0.3
B16: Rooms cost (% of rooms revenue) | D16: 0.1
B17: Utilities (% of total revenue) | D17: 0.05
B18: Sales & marketing (% of revenue) | D18: 0.06
B19: Admin & general (% of revenue) | D19: 0.05
B20: Property: rent/rates/insurance (%) | D20: 0.12
B22: CAPITAL EXPENDITURE (FIT-OUT LED — LEASED PROPERTY)
B23: Lease deposit & legal | D23: 45000
B24: Building refurbishment & fit-out | D24: 240000
B25: FF&E (rooms, beds, furniture) | D25: 120000
B26: Kitchen & F&B equipment | D26: 55000
B27: IT, PMS, POS & networking | D27: 30000
B28: Branding, signage & website | D28: 25000
B29: Pre-opening payroll & training | D29: 35000
B30: Working capital buffer | D30: 50000
B31: Total capex required | D31: =SUM(D23:D30)
B33: FUNDING MIX
B34: Founder equity (incl. SURE refund) | D34: 180000 | F34: =IF($D$34="","",D34/SUM($D$34:$D$37))
B35: LEO Priming grant | D35: 80000 | F35: =IF($D$35="","",D35/SUM($D$34:$D$37))
B36: Bank / SBCI term loan | D36: 300000 | F36: =IF($D$36="","",D36/SUM($D$34:$D$37))
B37: Microfinance Ireland loan | D37: 40000 | F37: =IF($D$37="","",D37/SUM($D$34:$D$37))
B38: Total funding raised | D38: =SUM(D34:D37)
B39: Funding vs capex (surplus/gap) | D39: ='Assumptions'!D38-'Assumptions'!D31
B41: SOURCES & BENCHMARK NOTES
B42: ADR/occupancy/RevPAR benchmarks: Fáilte Ireland & STR Ireland hotel performance reports (4-star/boutique ranges).
B43: Grant/funding figures: Local Enterprise Office (localenterprise.ie), Microfinance Ireland, SBCI, Fáilte Ireland investment schemes.
B44: Cost ratios (payroll ~30%, F&B cost ~30%): USALI hotel P&L conventions.
B45: Figures are seed assumptions — replace the orange cells with your own quotes and verified local data before relying on them.
...
