Workbook

Sheet Business Plan
B1: Microfinance Ireland — Loan Application
B2: Business loans €2,000–€50,000 · business plan + cash-flow
B4: Loans above €5,000 require a business plan and a month-by-month cash-flow. Apply via your LEO for a 1% rate discount + mentor support. Source: microfinanceireland.ie.
B5: LOAN REQUEST
B6: Amount requested € | D6: 40000
B7: Purpose of loan
B8: Term (months) | D8: 36
B10: Business summary
B11: What the business does, stage, and why now.
B13: Promoter & experience
B14: Your background and relevant experience.
B16: Market & customers
B17: Demand, target customers, and competition.
B19: How the loan will be repaid
B20: Link to the cash-flow forecast sheet.

Sheet Cashflow Forecast
B1: 12-Month Cash-Flow Forecast
B2: Month-by-month — required for loans above €5,000
B4: Line (€) | C4: M1 | D4: M2 | E4: M3 | F4: M4 | G4: M5 | H4: M6 | I4: M7 | J4: M8 | K4: M9 | L4: M10 | M4: M11 | N4: M12 | O4: Year
B5: Occupancy ramp × | C5: 0.45 | D5: 0.55 | E5: 0.62 | F5: 0.68 | G5: 0.74 | H5: 0.8 | I5: 0.85 | J5: 0.88 | K5: 0.85 | L5: 0.8 | M5: 0.74 | N5: 0.7
B6: Cash in — revenue | C6: =('Assumptions'!D11/12)*(C5/'Assumptions'!D7) | D6: =('Assumptions'!D11/12)*(D5/'Assumptions'!D7) | E6: =('Assumptions'!D11/12)*(E5/'Assumptions'!D7) | F6: =('Assumptions'!D11/12)*(F5/'Assumptions'!D7) | G6: =('Assumptions'!D11/12)*(G5/'Assumptions'!D7) | H6: =('Assumptions'!D11/12)*(H5/'Assumptions'!D7) | I6: =('Assumptions'!D11/12)*(I5/'Assumptions'!D7) | J6: =('Assumptions'!D11/12)*(J5/'Assumptions'!D7) | K6: =('Assumptions'!D11/12)*(K5/'Assumptions'!D7) | L6: =('Assumptions'!D11/12)*(L5/'Assumptions'!D7) | M6: =('Assumptions'!D11/12)*(M5/'Assumptions'!D7) | N6: =('Assumptions'!D11/12)*(N5/'Assumptions'!D7) | O6: =SUM(C6:N6)
B7: Payroll | C7: =C6*'Assumptions'!D14 | D7: =D6*'Assumptions'!D14 | E7: =E6*'Assumptions'!D14 | F7: =F6*'Assumptions'!D14 | G7: =G6*'Assumptions'!D14 | H7: =H6*'Assumptions'!D14 | I7: =I6*'Assumptions'!D14 | J7: =J6*'Assumptions'!D14 | K7: =K6*'Assumptions'!D14 | L7: =L6*'Assumptions'!D14 | M7: =M6*'Assumptions'!D14 | N7: =N6*'Assumptions'!D14 | O7: =SUM(C7:N7)
B8: Other operating costs | C8: =C6*('Assumptions'!D15*'Assumptions'!D9+'Assumptions'!D16+'Assumptions'!D17+'Assumptions'!D18+'Assumptions'!D19+'Assumptions'!D20) | D8: =D6*('Assumptions'!D15*'Assumptions'!D9+'Assumptions'!D16+'Assumptions'!D17+'Assumptions'!D18+'Assumptions'!D19+'Assumptions'!D20) | E8: =E6*('Assumptions'!D15*'Assumptions'!D9+'Assumptions'!D16+'Assumptions'!D17+'Assumptions'!D18+'Assumptions'!D19+'Assumptions'!D20) | F8: =F6*('Assumptions'!D15*'Assumptions'!D9+'Assumptions'!D16+'Assumptions'!D17+'Assumptions'!D18+'Assumptions'!D19+'Assumptions'!D20) | G8: =G6*('Assumptions'!D15*'Assumptions'!D9+'Assumptions'!D16+'Assumptions'!D17+'Assumptions'!D18+'Assumptions'!D19+'Assumptions'!D20) | H8: =H6*('Assumptions'!D15*'Assumptions'!D9+'Assumptions'!D16+'Assumptions'!D17+'Assumptions'!D18+'Assumptions'!D19+'Assumptions'!D20) | I8: =I6*('Assumptions'!D15*'Assumptions'!D9+'Assumptions'!D16+'Assumptions'!D17+'Assumptions'!D18+'Assumptions'!D19+'Assumptions'!D20) | J8: =J6*('Assumptions'!D15*'Assumptions'!D9+'Assumptions'!D16+'Assumptions'!D17+'Assumptions'!D18+'Assumptions'!D19+'Assumptions'!D20) | K8: =K6*('Assumptions'!D15*'Assumptions'!D9+'Assumptions'!D16+'Assumptions'!D17+'Assumptions'!D18+'Assumptions'!D19+'Assumptions'!D20) | L8: =L6*('Assumptions'!D15*'Assumptions'!D9+'Assumptions'!D16+'Assumptions'!D17+'Assumptions'!D18+'Assumptions'!D19+'Assumptions'!D20) | M8: =M6*('Assumptions'!D15*'Assumptions'!D9+'Assumptions'!D16+'Assumptions'!D17+'Assumptions'!D18+'Assumptions'!D19+'Assumptions'!D20) | N8: =N6*('Assumptions'!D15*'Assumptions'!D9+'Assumptions'!D16+'Assumptions'!D17+'Assumptions'!D18+'Assumptions'!D19+'Assumptions'!D20) | O8: =SUM(C8:N8)
B9: Loan repayment | C9: =1133 | D9: =1133 | E9: =1133 | F9: =1133 | G9: =1133 | H9: =1133 | I9: =1133 | J9: =1133 | ... N9: =1133 | O9: =SUM(C9:N9)
B10: Net cash flow | C10: =C6-C7-C8-C9 | D10: =D6-D7-D8-D9 | E10: =E6-E7-E8-E9 | F10: =F6-F7-F8-F9 | G10: =G6-G7-G8-G9 | H10: =H6-H7-H8-H9 | I10: =I6-I7-I8-I9 | J10: =J6-J7-J8-J9 | ... N10: =N6-N7-N8-N9 | O10: =SUM(C10:N10)
B11: Opening cash | C11: ='Assumptions'!D38-'Assumptions'!D31 | D11: =C12 | E11: =D12 | F11: =E12 | G11: =F12 | H11: =G12 | I11: =H12 | J11: =I12 | K11: =J12 | ... N11: =M12
B12: Closing cash | C12: =C11+C10 | D12: =D11+D10 | E12: =E11+E10 | F12: =F11+F10 | G12: =G11+G10 | H12: =H11+H10 | I12: =I11+I10 | J12: =J11+J10 | ... N12: =N11+N10 | O12: =N12
B13: Lowest closing cash € | C13: =MIN(C12:N12)

Sheet Assumptions
B1: Assumptions & Inputs
B2: Single source of truth — edit the orange cells; everything links here
B4: DEMAND & RATE
B5: Rooms available | D5: 24
B6: ADR — average daily rate | D6: 135 | F6: 4★ boutique IE €110–180
B7: Occupancy | D7: 0.72 | F7: annualised; 65–80% typical
B8: RevPAR (ADR × occupancy) | D8: ='Assumptions'!D6*'Assumptions'!D7
B9: F&B + other revenue (% of rooms) | D9: 0.28
B10: Rooms revenue / yr | D10: ='Assumptions'!D5*365*'Assumptions'!D8
B11: Total revenue / yr | D11: ='Assumptions'!D10*(1+'Assumptions'!D9)
B13: COST RATIOS
B14: Payroll (% of total revenue) | D14: 0.3
B15: F&B cost (% of F&B revenue) | D15: 0.3
B16: Rooms cost (% of rooms revenue) | D16: 0.1
B17: Utilities (% of total revenue) | D17: 0.05
B18: Sales & marketing (% of revenue) | D18: 0.06
B19: Admin & general (% of revenue) | D19: 0.05
B20: Property: rent/rates/insurance (%) | D20: 0.12
B22: CAPITAL EXPENDITURE (FIT-OUT LED — LEASED PROPERTY)
B23: Lease deposit & legal | D23: 45000
B24: Building refurbishment & fit-out | D24: 240000
B25: FF&E (rooms, beds, furniture) | D25: 120000
B26: Kitchen & F&B equipment | D26: 55000
B27: IT, PMS, POS & networking | D27: 30000
B28: Branding, signage & website | D28: 25000
B29: Pre-opening payroll & training | D29: 35000
B30: Working capital buffer | D30: 50000
B31: Total capex required | D31: =SUM(D23:D30)
B33: FUNDING MIX
B34: Founder equity (incl. SURE refund) | D34: 180000 | F34: =IF($D$34="","",D34/SUM($D$34:$D$37))
B35: LEO Priming grant | D35: 80000 | F35: =IF($D$35="","",D35/SUM($D$34:$D$37))
B36: Bank / SBCI term loan | D36: 300000 | F36: =IF($D$36="","",D36/SUM($D$34:$D$37))
B37: Microfinance Ireland loan | D37: 40000 | F37: =IF($D$37="","",D37/SUM($D$34:$D$37))
B38: Total funding raised | D38: =SUM(D34:D37)
B39: Funding vs capex (surplus/gap) | D39: ='Assumptions'!D38-'Assumptions'!D31
B41: SOURCES & BENCHMARK NOTES
B42: ADR/occupancy/RevPAR: Fáilte Ireland Hotel Survey 2024 — 4★ ADR €143.50–€144.49, occupancy 60.2% (Dec) → 74.1% (Nov), RevPAR €86.42–€107.07.
B43: Cost ratios: hospitality labour 25–35% of revenue (US long-run 31.2%); USALI F&B cost-of-sales; GOP margin ~36–38% (HotelData 2025). See `startup_benchmarks` table.
B44: Grant/funding figures: Local Enterprise Office (localenterprise.ie), Microfinance Ireland, SBCI, Fáilte Ireland investment schemes.
B45: Figures are seed assumptions — replace the orange cells with your own quotes and verified local data before relying on them.
...
